Traceback (most recent call last):
  File "/eos/user/z/zhenxuan/hhwwgg/QCD_HT200to300_2017/job_11/QCD_HT200to300_2017_executable_job11.py", line 4, in <module>
    from higgs_dna.analysis import run_analysis
  File "/afs/cern.ch/user/z/zhenxuan/HiggsDNA/higgs_dna/analysis.py", line 10, in <module>
    import uproot
  File "/eos/user/z/zhenxuan/higgs-dna/lib/python3.10/site-packages/uproot/__init__.py", line 78, in <module>
    import uproot.extras
  File "/eos/user/z/zhenxuan/higgs-dna/lib/python3.10/site-packages/uproot/extras.py", line 15, in <module>
    import pkg_resources
  File "/eos/user/z/zhenxuan/higgs-dna/lib/python3.10/site-packages/pkg_resources/__init__.py", line 33, in <module>
    import email.parser
  File "/eos/user/z/zhenxuan/higgs-dna/lib/python3.10/email/parser.py", line 12, in <module>
    from email.feedparser import FeedParser, BytesFeedParser
  File "<frozen importlib._bootstrap>", line 1027, in _find_and_load
  File "<frozen importlib._bootstrap>", line 1006, in _find_and_load_unlocked
  File "<frozen importlib._bootstrap>", line 688, in _load_unlocked
  File "<frozen importlib._bootstrap_external>", line 879, in exec_module
  File "<frozen importlib._bootstrap_external>", line 1016, in get_code
  File "<frozen importlib._bootstrap_external>", line 1074, in get_data
OSError: [Errno 5] Input/output error
